Workbook

Sheet  911 Admin
A1: City of Altamonte Springs, Florida
A2: ='[1]Admin Summary'!A2:K2 -> Fiscal Year 2026 / 2027 Annual Budget
A4: Leisure and Maintenance Services Department
A5: Administration Division
A6: General Fund (00109110)
M8: ='[1]WS 818'!M8 -> 2027
G9: ='[1]WS 818'!G9 -> 2024 | I9: ='[1]WS 818'!I9 -> 2025 | K9: ='[1]WS 818'!K9 -> 2026 | M9: Department | O9: Manager | Q9: Commission
B10: Org | C10: Obj | D10: Proj | G10: Actual | I10: Actual | K10: Budget | M10: Requested | O10: Recommended | Q10: Adopted | R10: Notes
A11: PERSONNEL SERVICES
A12: Regular Salaries & Wages Base: 9 Positions | B12: 00109110 | C12: 501201 | E12: =_xlfn.CONCAT(B12,C12,D12) -> 00109110501201 | F12: $ | G12: =ROUND(IFERROR(VLOOKUP(_xlfn.CONCAT($B12,$C12,$D12),$A$73:$C$9993,3,FALSE),0),0) -> 682482 | H12: $ | I12: =ROUND(IFERROR(VLOOKUP(_xlfn.CONCAT($B12,$C12,$D12),$A$73:$C$9993,2,FALSE),0),0) -> 715227 | J12: $ | K12: 673169 | L12: $ | M12: ='[1]Payroll Summary by Department'!C60 -> 673169 | N12: $ | O12: ='[1]Payroll Summary by Department'!C60 -> 673169 | P12: $ | Q12: =O12 -> 673169
A13: Limited Term - Intern | B13: 00109110 | C13: 501315 | E13: =_xlfn.CONCAT(B13,C13,D13) -> 00109110501315 | G13: =ROUND(IFERROR(VLOOKUP(_xlfn.CONCAT($B13,$C13,$D13),$A$73:$C$9993,3,FALSE),0),0) -> 7823 | I13: =ROUND(IFERROR(VLOOKUP(_xlfn.CONCAT($B13,$C13,$D13),$A$73:$C$9993,2,FALSE),0),0) -> 11689 | K13: 21000 | M13: 21000 | O13: =M13 -> 21000 | Q13: =O13 -> 21000
A14: Overtime | B14: 00109110 | C14: 501400 | E14: =_xlfn.CONCAT(B14,C14,D14) -> 00109110501400 | G14: =ROUND(IFERROR(VLOOKUP(_xlfn.CONCAT($B14,$C14,$D14),$A$73:$C$9993,3,FALSE),0),0) -> 1100 | I14: =ROUND(IFERROR(VLOOKUP(_xlfn.CONCAT($B14,$C14,$D14),$A$73:$C$9993,2,FALSE),0),0) -> 2658 | K14: 1000 | M14: 1000 | O14: =M14 -> 1000 | Q14: =O14 -> 1000
A15: On-Call | B15: 00109110 | C15: 501401 | E15: =_xlfn.CONCAT(B15,C15,D15) -> 00109110501401 | G15: =ROUND(IFERROR(VLOOKUP(_xlfn.CONCAT($B15,$C15,$D15),$A$73:$C$9993,3,FALSE),0),0) -> 0 | I15: =ROUND(IFERROR(VLOOKUP(_xlfn.CONCAT($B15,$C15,$D15),$A$73:$C$9993,2,FALSE),0),0) -> 0 | K15: 0 | M15: 0 | O15: =M15 -> 0 | Q15: =O15 -> 0
A16: Add Pays | B16: 00109110 | C16: 501600 | E16: =_xlfn.CONCAT(B16,C16,D16) -> 00109110501600 | G16: =ROUND(IFERROR(VLOOKUP(_xlfn.CONCAT($B16,$C16,$D16),$A$73:$C$9993,3,FALSE),0),0) -> 0 | I16: =ROUND(IFERROR(VLOOKUP(_xlfn.CONCAT($B16,$C16,$D16),$A$73:$C$9993,2,FALSE),0),0) -> 0 | K16: 0 | M16: ='[1]Payroll Summary by Department'!I60 -> 0 | O16: =M16 -> 0 | Q16: =O16 -> 0
A17: Auto Allowance | B17: 00109110 | C17: 501701 | E17: =_xlfn.CONCAT(B17,C17,D17) -> 00109110501701 | G17: =ROUND(IFERROR(VLOOKUP(_xlfn.CONCAT($B17,$C17,$D17),$A$73:$C$9993,3,FALSE),0),0) -> 12040 | I17: =ROUND(IFERROR(VLOOKUP(_xlfn.CONCAT($B17,$C17,$D17),$A$73:$C$9993,2,FALSE),0),0) -> 12049 | K17: 12000 | M17: ='[1]Payroll Summary by Department'!K60 -> 12000 | O17: =M17 -> 12000 | Q17: =O17 -> 12000
A18: Cell Phone Allowance | B18: 00109110 | C18: 501702 | E18: =_xlfn.CONCAT(B18,C18,D18) -> 00109110501702 | G18: =ROUND(IFERROR(VLOOKUP(_xlfn.CONCAT($B18,$C18,$D18),$A$73:$C$9993,3,FALSE),0),0) -> 6623 | I18: =ROUND(IFERROR(VLOOKUP(_xlfn.CONCAT($B18,$C18,$D18),$A$73:$C$9993,2,FALSE),0),0) -> 6811 | K18: 6600 | M18: ='[1]Payroll Summary by Department'!L60 -> 6600 | O18: =M18 -> 6600 | Q18: =O18 -> 6600
A19: Uniform Allowance | B19: 00109110 | C19: 501800 | E19: =_xlfn.CONCAT(B19,C19,D19) -> 00109110501800 | G19: =ROUND(IFERROR(VLOOKUP(_xlfn.CONCAT($B19,$C19,$D19),$A$73:$C$9993,3,FALSE),0),0) -> 0 | I19: =ROUND(IFERROR(VLOOKUP(_xlfn.CONCAT($B19,$C19,$D19),$A$73:$C$9993,2,FALSE),0),0) -> 0 | K19: 50 | M19: 50 | O19: =M19 -> 50 | Q19: =O19 -> 50
A20: FICA Taxes | B20: 00109110 | C20: 502100 | E20: =_xlfn.CONCAT(B20,C20,D20) -> 00109110502100 | G20: =ROUND(IFERROR(VLOOKUP(_xlfn.CONCAT($B20,$C20,$D20),$A$73:$C$9993,3,FALSE),0),0) -> 53677 | I20: =ROUND(IFERROR(VLOOKUP(_xlfn.CONCAT($B20,$C20,$D20),$A$73:$C$9993,2,FALSE),0),0) -> 56288 | K20: 54607 | M20: ='[1]Payroll Summary by Department'!N60 -> 54607 | O20: ='[1]Payroll Summary by Department'!N60 -> 54607 | Q20: =O20 -> 54607
A21: Retirement Contributions | B21: 00109110 | C21: 502200 | E21: =_xlfn.CONCAT(B21,C21,D21) -> 00109110502200 | G21: =ROUND(IFERROR(VLOOKUP(_xlfn.CONCAT($B21,$C21,$D21),$A$73:$C$9993,3,FALSE),0),0) -> 83410 | I21: =ROUND(IFERROR(VLOOKUP(_xlfn.CONCAT($B21,$C21,$D21),$A$73:$C$9993,2,FALSE),0),0) -> 84375 | K21: 100961 | M21: ='[1]Payroll Summary by Department'!O60+'[1]Payroll Summary by Department'!P60 -> 100961 | O21: ='[1]Payroll Summary by Department'!O60+'[1]Payroll Summary by Department'!P60 -> 100961 | Q21: =O21 -> 100961
A22: Health Insurance | B22: 00109110 | C22: 502300 | E22: =_xlfn.CONCAT(B22,C22,D22) -> 00109110502300 | G22: =ROUND(IFERROR(VLOOKUP(_xlfn.CONCAT($B22,$C22,$D22),$A$73:$C$9993,3,FALSE),0),0) -> 82199 | I22: =ROUND(IFERROR(VLOOKUP(_xlfn.CONCAT($B22,$C22,$D22),$A$73:$C$9993,2,FALSE),0),0) -> 87748 | K22: 102160 | M22: ='[1]Payroll Summary by Department'!Q60 -> 102160 | O22: ='[1]Payroll Summary by Department'!Q60 -> 102160 | Q22: =O22 -> 102160
A23: Life Insurance | B23: 00109110 | C23: 502400 | E23: =_xlfn.CONCAT(B23,C23,D23) -> 00109110502400 | G23: =ROUND(IFERROR(VLOOKUP(_xlfn.CONCAT($B23,$C23,$D23),$A$73:$C$9993,3,FALSE),0),0) -> 1388 | I23: =ROUND(IFERROR(VLOOKUP(_xlfn.CONCAT($B23,$C23,$D23),$A$73:$C$9993,2,FALSE),0),0) -> 1409 | K23: 1272 | M23: ='[1]Payroll Summary by Department'!R60 -> 1272 | O23: ='[1]Payroll Summary by Department'!R60 -> 1272 | Q23: =O23 -> 1272
A24: Total Personnel Services | E24: =_xlfn.CONCAT(B24,C24,D24) | F24: $ | G24: =SUM(G12:G23) -> 930742 | H24: $ | I24: =SUM(I12:I23) -> 978254 | J24: $ | K24: =SUM(K12:K23) -> 972819 | L24: $ | M24: =SUM(M12:M23) -> 972819 | N24: $ | O24: =SUM(O12:O23) -> 972819 | P24: $ | Q24: =SUM(Q12:Q23) -> 972819
A25: POSITION ROSTER | E25: =_xlfn.CONCAT(B25,C25,D25)
A26: Full-Time Employees | E26: =_xlfn.CONCAT(B26,C26,D26)
A27: Director of Leisure Services | C27: 1D | E27: =_xlfn.CONCAT(B27,C27,D27) -> 1D | G27: 1 | I27: 1 | K27: =I27 -> 1 | M27: =K27 -> 1 | O27: =M27 -> 1 | Q27: =O27 -> 1
A28: Recreation Division Director | C28: 2A | E28: =_xlfn.CONCAT(B28,C28,D28) -> 2A | G28: 1 | I28: 1 | K28: =I28 -> 1 | M28: =K28 -> 1 | O28: =M28 -> 1 | Q28: =O28 -> 1
A29: Parks & Grounds Div. Director | C29: 2A | E29: =_xlfn.CONCAT(B29,C29,D29) -> 2A | G29: 1 | I29: 1 | K29: =I29 -> 1 | M29: =K29 -> 1 | O29: =M29 -> 1 | Q29: =O29 -> 1
A30: Fleet & Facilities Division Director | C30: 2A | E30: =_xlfn.CONCAT(B30,C30,D30) -> 2A | G30: 1 | I30: 1 | K30: =I30 -> 1 | M30: =K30 -> 1 | O30: =M30 -> 1 | Q30: =O30 -> 1
A31: Administrative Manager | C31: 3C | E31: =_xlfn.CONCAT(B31,C31,D31) -> 3C | G31: 1 | I31: 1 | K31: =I31 -> 1 | M31: =K31 -> 1 | O31: =M31 -> 1 | Q31: =O31 -> 1
A32: Fiscal Manager | C32: 3B | E32: =_xlfn.CONCAT(B32,C32,D32) -> 3B | G32: 1 | I32: 1 | K32: =I32 -> 1 | M32: =K32 -> 1 | O32: =M32 -> 1 | Q32: =O32 -> 1
A33: Office Administrator | C33: 3B | E33: =_xlfn.CONCAT(B33,C33,D33) -> 3B | G33: 0 | I33: 0 | K33: =I33 -> 0 | M33: =K33 -> 0 | O33: =M33 -> 0 | Q33: =O33 -> 0
A34: Staff Assistant | C34: 4C | E34: =_xlfn.CONCAT(B34,C34,D34) -> 4C | G34: 2 | I34: 2 | K34: =I34 -> 2 | M34: =K34 -> 2 | O34: =M34 -> 2 | Q34: =O34 -> 2
A35: Deputy Director | C35: 2B | E35: =_xlfn.CONCAT(B35,C35,D35) -> 2B | G35: 0 | I35: 0 | K35: =I35 -> 0 | M35: =K35 -> 0 | O35: =M35 -> 0 | Q35: =O35 -> 0
A36: Recreation Support Administrator | C36: 3B | E36: =_xlfn.CONCAT(B36,C36,D36) -> 3B | G36: 1 | I36: 1 | K36: =I36 -> 1 | M36: =K36 -> 1 | O36: =M36 -> 1 | Q36: =O36 -> 1
A37: PLMO Specialist | C37: 4C | E37: =_xlfn.CONCAT(B37,C37,D37) -> 4C | G37: 1 | I37: 1 | K37: =I37 -> 1 | M37: =K37 -> 1 | O37: =M37 -> 1 | Q37: =O37 -> 1
E38: =_xlfn.CONCAT(B38,C38,D38)
A39: Total Positions | E39: =_xlfn.CONCAT(B39,C39,D39) | G39: =SUM(G27:G38) -> 10 | I39: =SUM(I27:I38) -> 10 | K39: =SUM(K27:K38) -> 10 | M39: =SUM(M27:M38) -> 10 | O39: =SUM(O27:O38) -> 10 | Q39: =SUM(Q27:Q38) -> 10
A40: OPERATING EXPENDITURES | E40: =_xlfn.CONCAT(B40,C40,D40)
A41: Other Services-Software Subscriptions | B41: 00109110 | C41: 503403 | E41: =_xlfn.CONCAT(B41,C41,D41) -> 00109110503403 | F41: $ | G41: =ROUND(IFERROR(VLOOKUP(_xlfn.CONCAT($B41,$C41,$D41),$A$73:$C$9993,3,FALSE),0),0) -> 2717 | H41: $ | I41: =ROUND(IFERROR(VLOOKUP(_xlfn.CONCAT($B41,$C41,$D41),$A$73:$C$9993,2,FALSE),0),0) -> 2807 | J41: $ | K41: 0 | L41: $ | M41: 0 | N41: $ | O41: =M41 -> 0 | P41: $ | Q41: =O41 -> 0
A42: All Parks-Playgrd Inspec. Software | B42: 00109110 | E42: =_xlfn.CONCAT(B42,C42,D42) -> 00109110 | G42: =ROUND(IFERROR(VLOOKUP(_xlfn.CONCAT($B42,$C42,$D42),$A$73:$C$9993,3,FALSE),0),0) -> 0 | I42: =ROUND(IFERROR(VLOOKUP(_xlfn.CONCAT($B42,$C42,$D42),$A$73:$C$9993,2,FALSE),0),0) -> 0 | K42: 2500 | M42: 2500 | O42: =M42 -> 2500 | Q42: =O42 -> 2500
...

Sheet 912 Eastmonte
A1: City of Altamonte Springs, Florida
A2: ='[1]Admin Summary'!A2:K2 -> Fiscal Year 2026 / 2027 Annual Budget
A4: Leisure and Maintenance Services Department
A5: Eastmonte Park
A6: General Fund (00109120)
M8: =' 911 Admin'!M8 -> 2027
G9: =' 911 Admin'!G9 -> 2024 | I9: =' 911 Admin'!I9 -> 2025 | K9: =' 911 Admin'!K9 -> 2026 | M9: Department | O9: Manager | Q9: Commission
B10: Org | C10: Obj | D10: Proj | G10: Actual | I10: Actual | K10: Budget | M10: Requested | O10: Recommended | Q10: Adopted | R10: Notes
A11: PERSONNEL SERVICES
A12: Regular Salaries & Wages | B12: 00109120 | C12: 501201 | E12: =_xlfn.CONCAT(B12,C12,D12) -> 00109120501201 | F12: $ | G12: =ROUND(IFERROR(VLOOKUP(_xlfn.CONCAT($B12,$C12,$D12),$A$66:$C$9993,3,FALSE),0),0) -> 0 | H12: $ | I12: =ROUND(IFERROR(VLOOKUP(_xlfn.CONCAT($B12,$C12,$D12),$A$66:$C$9993,2,FALSE),0),0) -> 428 | J12: $ | K12: 0 | L12: $ | M12: ='[1]Payroll Summary by Department'!C61 -> 0 | N12: $ | O12: =M12 -> 0 | P12: $ | Q12: =O12 -> 0
A13: Limited Term Employee Wages | B13: 00109120 | C13: 501305 | E13: =_xlfn.CONCAT(B13,C13,D13) -> 00109120501305 | G13: =ROUND(IFERROR(VLOOKUP(_xlfn.CONCAT($B13,$C13,$D13),$A$66:$C$9993,3,FALSE),0),0) -> 18236 | I13: =ROUND(IFERROR(VLOOKUP(_xlfn.CONCAT($B13,$C13,$D13),$A$66:$C$9993,2,FALSE),0),0) -> 20223 | K13: 25000 | M13: 25000 | O13: =M13 -> 25000 | Q13: =O13 -> 25000
A14: Overtime | B14: 00109120 | C14: 501400 | E14: =_xlfn.CONCAT(B14,C14,D14) -> 00109120501400 | G14: =ROUND(IFERROR(VLOOKUP(_xlfn.CONCAT($B14,$C14,$D14),$A$66:$C$9993,3,FALSE),0),0) -> 43 | I14: =ROUND(IFERROR(VLOOKUP(_xlfn.CONCAT($B14,$C14,$D14),$A$66:$C$9993,2,FALSE),0),0) -> 275 | K14: 0 | M14: 0 | O14: =M14 -> 0 | Q14: =O14 -> 0
A15: Add Pays | B15: 00109120 | C15: 501600 | E15: =_xlfn.CONCAT(B15,C15,D15) -> 00109120501600 | G15: =ROUND(IFERROR(VLOOKUP(_xlfn.CONCAT($B15,$C15,$D15),$A$66:$C$9993,3,FALSE),0),0) -> 0 | I15: =ROUND(IFERROR(VLOOKUP(_xlfn.CONCAT($B15,$C15,$D15),$A$66:$C$9993,2,FALSE),0),0) -> 0 | K15: 0 | M15: ='[1]Payroll Summary by Department'!I61 -> 0 | O15: =M15 -> 0 | Q15: =O15 -> 0
A16: Uniform Allowance | B16: 00109120 | C16: 501800 | E16: =_xlfn.CONCAT(B16,C16,D16) -> 00109120501800 | G16: =ROUND(IFERROR(VLOOKUP(_xlfn.CONCAT($B16,$C16,$D16),$A$66:$C$9993,3,FALSE),0),0) -> 0 | I16: =ROUND(IFERROR(VLOOKUP(_xlfn.CONCAT($B16,$C16,$D16),$A$66:$C$9993,2,FALSE),0),0) -> 0 | K16: 0 | M16: 0 | O16: =M16 -> 0 | Q16: =O16 -> 0
A17: FICA Taxes | B17: 00109120 | C17: 502100 | E17: =_xlfn.CONCAT(B17,C17,D17) -> 00109120502100 | G17: =ROUND(IFERROR(VLOOKUP(_xlfn.CONCAT($B17,$C17,$D17),$A$66:$C$9993,3,FALSE),0),0) -> 1398 | I17: =ROUND(IFERROR(VLOOKUP(_xlfn.CONCAT($B17,$C17,$D17),$A$66:$C$9993,2,FALSE),0),0) -> 1601 | K17: 1913 | M17: ='[1]Payroll Summary by Department'!N61 -> 1913 | O17: =M17 -> 1913 | Q17: =O17 -> 1913
A18: Retirement Contributions | B18: 00109120 | C18: 502200 | E18: =_xlfn.CONCAT(B18,C18,D18) -> 00109120502200 | G18: =ROUND(IFERROR(VLOOKUP(_xlfn.CONCAT($B18,$C18,$D18),$A$66:$C$9993,3,FALSE),0),0) -> 0 | I18: =ROUND(IFERROR(VLOOKUP(_xlfn.CONCAT($B18,$C18,$D18),$A$66:$C$9993,2,FALSE),0),0) -> 0 | K18: 0 | M18: ='[1]Payroll Summary by Department'!O61+'[1]Payroll Summary by Department'!P61 -> 0 | O18: =M18 -> 0 | Q18: =O18 -> 0
A19: Health Insurance | B19: 00109120 | C19: 502300 | E19: =_xlfn.CONCAT(B19,C19,D19) -> 00109120502300 | G19: =ROUND(IFERROR(VLOOKUP(_xlfn.CONCAT($B19,$C19,$D19),$A$66:$C$9993,3,FALSE),0),0) -> 0 | I19: =ROUND(IFERROR(VLOOKUP(_xlfn.CONCAT($B19,$C19,$D19),$A$66:$C$9993,2,FALSE),0),0) -> 0 | K19: 0 | M19: ='[1]Payroll Summary by Department'!Q61 -> 0 | O19: =M19 -> 0 | Q19: =O19 -> 0
A20: Life Insurance | B20: 00109120 | C20: 502400 | E20: =_xlfn.CONCAT(B20,C20,D20) -> 00109120502400 | G20: =ROUND(IFERROR(VLOOKUP(_xlfn.CONCAT($B20,$C20,$D20),$A$66:$C$9993,3,FALSE),0),0) -> 0 | I20: =ROUND(IFERROR(VLOOKUP(_xlfn.CONCAT($B20,$C20,$D20),$A$66:$C$9993,2,FALSE),0),0) -> 0 | K20: 0 | M20: ='[1]Payroll Summary by Department'!R61 -> 0 | O20: =M20 -> 0 | Q20: =O20 -> 0
A21: Total Personnel Services | E21: =_xlfn.CONCAT(B21,C21,D21) | F21: $ | G21: =SUM(G12:G20) -> 19677 | H21: $ | I21: =SUM(I12:I20) -> 22527 | J21: $ | K21: =SUM(K12:K20) -> 26913 | L21: $ | M21: =SUM(M12:M20) -> 26913 | N21: $ | O21: =SUM(O12:O20) -> 26913 | P21: $ | Q21: =SUM(Q12:Q20) -> 26913
A22: POSITION ROSTER | E22: =_xlfn.CONCAT(B22,C22,D22)
A23: Full-Time Employees | E23: =_xlfn.CONCAT(B23,C23,D23)
A24: Staff Assistant | C24: 4C | E24: =_xlfn.CONCAT(B24,C24,D24) -> 4C | G24: 0 | I24: 0 | K24: 0 | M24: 0 | O24: =M24 -> 0 | Q24: =O24 -> 0
A25: Total Positions | E25: =_xlfn.CONCAT(B25,C25,D25) | G25: =SUM(G24:G24) -> 0 | I25: =SUM(I24:I24) -> 0 | K25: =SUM(K24:K24) -> 0 | M25: =SUM(M24:M24) -> 0 | O25: =SUM(O24:O24) -> 0 | Q25: =SUM(Q24:Q24) -> 0
A26: OPERATING EXPENDITURES | E26: =_xlfn.CONCAT(B26,C26,D26)
A27: Other Services-Bank Fees | B27: 00109120 | C27: 503415 | E27: =_xlfn.CONCAT(B27,C27,D27) -> 00109120503415 | F27: $ | G27: =ROUND(IFERROR(VLOOKUP(_xlfn.CONCAT($B27,$C27,$D27),$A$66:$C$9993,3,FALSE),0),0) -> 0 | H27: $ | I27: =ROUND(IFERROR(VLOOKUP(_xlfn.CONCAT($B27,$C27,$D27),$A$66:$C$9993,2,FALSE),0),0) -> 0 | J27: $ | K27: 0 | L27: $ | M27: 0 | N27: $ | O27: =M27 -> 0 | P27: $ | Q27: =O27 -> 0
A28: Other Services-Temporary Labor | B28: 00109120 | C28: 503450 | E28: =_xlfn.CONCAT(B28,C28,D28) -> 00109120503450 | G28: =ROUND(IFERROR(VLOOKUP(_xlfn.CONCAT($B28,$C28,$D28),$A$66:$C$9993,3,FALSE),0),0) -> 0 | I28: =ROUND(IFERROR(VLOOKUP(_xlfn.CONCAT($B28,$C28,$D28),$A$66:$C$9993,2,FALSE),0),0) -> 0 | K28: 0 | M28: 0 | O28: =M28 -> 0 | Q28: =O28 -> 0
A29: Other Contractural Services | B29: 00109120 | C29: 503499 | E29: =_xlfn.CONCAT(B29,C29,D29) -> 00109120503499 | F29: $ | G29: =ROUND(IFERROR(VLOOKUP(_xlfn.CONCAT($B29,$C29,$D29),$A$66:$C$9993,3,FALSE),0),0) -> 0 | H29: $ | I29: =ROUND(IFERROR(VLOOKUP(_xlfn.CONCAT($B29,$C29,$D29),$A$66:$C$9993,2,FALSE),0),0) -> 0 | J29: $ | K29: 1600 | L29: $ | M29: 1600 | N29: $ | O29: =M29 -> 1600 | P29: $ | Q29: =O29 -> 1600
A30: Rental/Lease-Equipment | B30: 00109120 | C30: 504430 | E30: =_xlfn.CONCAT(B30,C30,D30) -> 00109120504430 | G30: =ROUND(IFERROR(VLOOKUP(_xlfn.CONCAT($B30,$C30,$D30),$A$66:$C$9993,3,FALSE),0),0) -> 0 | I30: =ROUND(IFERROR(VLOOKUP(_xlfn.CONCAT($B30,$C30,$D30),$A$66:$C$9993,2,FALSE),0),0) -> 0 | K30: 0 | M30: 0 | O30: =M30 -> 0 | Q30: =O30 -> 0
A31: Repair/Maint-Bldgs/ Facilities | B31: 00109120 | C31: 504601 | E31: =_xlfn.CONCAT(B31,C31,D31) -> 00109120504601 | G31: =ROUND(IFERROR(VLOOKUP(_xlfn.CONCAT($B31,$C31,$D31),$A$66:$C$9993,3,FALSE),0),0) -> 0 | I31: =ROUND(IFERROR(VLOOKUP(_xlfn.CONCAT($B31,$C31,$D31),$A$66:$C$9993,2,FALSE),0),0) -> 2997 | K31: 0 | M31: 0 | O31: =M31 -> 0 | Q31: =O31 -> 0
A32: Replace Signage | B32: 00109120 | E32: =_xlfn.CONCAT(B32,C32,D32) -> 00109120 | G32: =ROUND(IFERROR(VLOOKUP(_xlfn.CONCAT($B32,$C32,$D32),$A$66:$C$9993,3,FALSE),0),0) -> 0 | I32: =ROUND(IFERROR(VLOOKUP(_xlfn.CONCAT($B32,$C32,$D32),$A$66:$C$9993,2,FALSE),0),0) -> 0 | K32: 3000 | M32: 3000 | O32: =M32 -> 3000 | Q32: =O32 -> 3000
A33: Repair/Maint-Fencing/Security | B33: 00109120 | C33: 504602 | E33: =_xlfn.CONCAT(B33,C33,D33) -> 00109120504602 | G33: =ROUND(IFERROR(VLOOKUP(_xlfn.CONCAT($B33,$C33,$D33),$A$66:$C$9993,3,FALSE),0),0) -> 720 | I33: =ROUND(IFERROR(VLOOKUP(_xlfn.CONCAT($B33,$C33,$D33),$A$66:$C$9993,2,FALSE),0),0) -> 360 | K33: 5000 | M33: 5000 | O33: =M33 -> 5000 | Q33: =O33 -> 5000
A34: Repair/Maint-Civic Center | B34: 00109120 | C34: 504605 | E34: =_xlfn.CONCAT(B34,C34,D34) -> 00109120504605 | G34: =ROUND(IFERROR(VLOOKUP(_xlfn.CONCAT($B34,$C34,$D34),$A$66:$C$9993,3,FALSE),0),0) -> 0 | I34: =ROUND(IFERROR(VLOOKUP(_xlfn.CONCAT($B34,$C34,$D34),$A$66:$C$9993,2,FALSE),0),0) -> 79 | K34: 0 | M34: 0 | O34: =M34 -> 0 | Q34: =O34 -> 0
A35: Repair/Maint-Ballfield | B35: 00109120 | C35: 504610 | E35: =_xlfn.CONCAT(B35,C35,D35) -> 00109120504610 | G35: =ROUND(IFERROR(VLOOKUP(_xlfn.CONCAT($B35,$C35,$D35),$A$66:$C$9993,3,FALSE),0),0) -> 9860 | I35: =ROUND(IFERROR(VLOOKUP(_xlfn.CONCAT($B35,$C35,$D35),$A$66:$C$9993,2,FALSE),0),0) -> 6525 | K35: 0 | M35: 0 | O35: =M35 -> 0 | Q35: =O35 -> 0
A36: Synthetic Turf Maintenance Program | B36: 00109120 | E36: =_xlfn.CONCAT(B36,C36,D36) -> 00109120 | G36: =ROUND(IFERROR(VLOOKUP(_xlfn.CONCAT($B36,$C36,$D36),$A$66:$C$9993,3,FALSE),0),0) -> 0 | I36: =ROUND(IFERROR(VLOOKUP(_xlfn.CONCAT($B36,$C36,$D36),$A$66:$C$9993,2,FALSE),0),0) -> 0 | K36: 5500 | M36: 5500 | O36: =M36 -> 5500 | Q36: =O36 -> 5500
A37: Synthetic Turf Crumb Rubber | B37: 00109120 | E37: =_xlfn.CONCAT(B37,C37,D37) -> 00109120 | G37: =ROUND(IFERROR(VLOOKUP(_xlfn.CONCAT($B37,$C37,$D37),$A$66:$C$9993,3,FALSE),0),0) -> 0 | I37: =ROUND(IFERROR(VLOOKUP(_xlfn.CONCAT($B37,$C37,$D37),$A$66:$C$9993,2,FALSE),0),0) -> 0 | K37: 3000 | M37: 3000 | O37: =M37 -> 3000 | Q37: =O37 -> 3000
A38: Repair/Maint-Equipment | B38: 00109120 | C38: 504620 | E38: =_xlfn.CONCAT(B38,C38,D38) -> 00109120504620 | G38: =ROUND(IFERROR(VLOOKUP(_xlfn.CONCAT($B38,$C38,$D38),$A$66:$C$9993,3,FALSE),0),0) -> 5621 | I38: =ROUND(IFERROR(VLOOKUP(_xlfn.CONCAT($B38,$C38,$D38),$A$66:$C$9993,2,FALSE),0),0) -> 5322 | K38: 0 | M38: 0 | O38: =M38 -> 0 | Q38: =O38 -> 0
A39: Playground | B39: 00109120 | E39: =_xlfn.CONCAT(B39,C39,D39) -> 00109120 | G39: =ROUND(IFERROR(VLOOKUP(_xlfn.CONCAT($B39,$C39,$D39),$A$66:$C$9993,3,FALSE),0),0) -> 0 | I39: =ROUND(IFERROR(VLOOKUP(_xlfn.CONCAT($B39,$C39,$D39),$A$66:$C$9993,2,FALSE),0),0) -> 0 | K39: 5000 | M39: 5000 | O39: =M39 -> 5000 | Q39: =O39 -> 5000
A40: Groundcover | B40: 00109120 | E40: =_xlfn.CONCAT(B40,C40,D40) -> 00109120 | G40: =ROUND(IFERROR(VLOOKUP(_xlfn.CONCAT($B40,$C40,$D40),$A$66:$C$9993,3,FALSE),0),0) -> 0 | I40: =ROUND(IFERROR(VLOOKUP(_xlfn.CONCAT($B40,$C40,$D40),$A$66:$C$9993,2,FALSE),0),0) -> 0 | K40: 5000 | M40: 5000 | O40: =M40 -> 5000 | Q40: =O40 -> 5000
A41: ThorGuard | B41: 00109120 | E41: =_xlfn.CONCAT(B41,C41,D41) -> 00109120 | G41: =ROUND(IFERROR(VLOOKUP(_xlfn.CONCAT($B41,$C41,$D41),$A$66:$C$9993,3,FALSE),0),0) -> 0 | I41: =ROUND(IFERROR(VLOOKUP(_xlfn.CONCAT($B41,$C41,$D41),$A$66:$C$9993,2,FALSE),0),0) -> 0 | K41: 5000 | M41: 5000 | O41: =M41 -> 5000 | Q41: =O41 -> 5000
A42: Repair/Maint-Hardscape | B42: 00109120 | C42: 504675 | E42: =_xlfn.CONCAT(B42,C42,D42) -> 00109120504675 | G42: =ROUND(IFERROR(VLOOKUP(_xlfn.CONCAT($B42,$C42,$D42),$A$66:$C$9993,3,FALSE),0),0) -> 0 | I42: =ROUND(IFERROR(VLOOKUP(_xlfn.CONCAT($B42,$C42,$D42),$A$66:$C$9993,2,FALSE),0),0) -> 0 | K42: 6000 | M42: 6000 | O42: =M42 -> 6000 | Q42: =O42 -> 6000
...

Sheet  913 Merrill
A1: City of Altamonte Springs, Florida
A2: ='[1]Admin Summary'!A2:K2 -> Fiscal Year 2026 / 2027 Annual Budget
A4: Leisure and Maintenance Services Department
A5: Merrill Park
A6: General Fund (00109130)
M8: =' 911 Admin'!M8 -> 2027
G9: =' 911 Admin'!G9 -> 2024 | I9: =' 911 Admin'!I9 -> 2025 | K9: =' 911 Admin'!K9 -> 2026 | M9: Department | O9: Manager | Q9: Commission
B10: Org | C10: Obj | D10: Proj | G10: Actual | I10: Actual | K10: Budget | M10: Requested | O10: Recommended | Q10: Adopted | R10: Notes
A11: PERSONAL SERVICES
A12: Regular Salaries & Wages | B12: 00109130 | C12: 501201 | E12: =_xlfn.CONCAT(B12,C12,D12) -> 00109130501201 | F12: $ | G12: =ROUND(IFERROR(VLOOKUP(_xlfn.CONCAT($B12,$C12,$D12),$A$53:$C$9993,3,FALSE),0),0) -> 0 | H12: $ | I12: =ROUND(IFERROR(VLOOKUP(_xlfn.CONCAT($B12,$C12,$D12),$A$53:$C$9993,2,FALSE),0),0) -> 0 | J12: $ | K12: 0 | L12: $ | M12: ='[1]Payroll Summary by Department'!C62 -> 0 | N12: $ | O12: =M12 -> 0 | P12: $ | Q12: =O12 -> 0
A13: Overtime | B13: 00109130 | C13: 501400 | E13: =_xlfn.CONCAT(B13,C13,D13) -> 00109130501400 | G13: =ROUND(IFERROR(VLOOKUP(_xlfn.CONCAT($B13,$C13,$D13),$A$53:$C$9993,3,FALSE),0),0) -> 0 | I13: =ROUND(IFERROR(VLOOKUP(_xlfn.CONCAT($B13,$C13,$D13),$A$53:$C$9993,2,FALSE),0),0) -> 0 | K13: 0 | M13: 0 | O13: =M13 -> 0 | Q13: =O13 -> 0
A14: Uniform Allowance | B14: 00109130 | C14: 501800 | E14: =_xlfn.CONCAT(B14,C14,D14) -> 00109130501800 | G14: =ROUND(IFERROR(VLOOKUP(_xlfn.CONCAT($B14,$C14,$D14),$A$53:$C$9993,3,FALSE),0),0) -> 0 | I14: =ROUND(IFERROR(VLOOKUP(_xlfn.CONCAT($B14,$C14,$D14),$A$53:$C$9993,2,FALSE),0),0) -> 0 | K14: 0 | M14: 0 | O14: =M14 -> 0 | Q14: =O14 -> 0
A15: FICA Taxes | B15: 00109130 | C15: 502100 | E15: =_xlfn.CONCAT(B15,C15,D15) -> 00109130502100 | G15: =ROUND(IFERROR(VLOOKUP(_xlfn.CONCAT($B15,$C15,$D15),$A$53:$C$9993,3,FALSE),0),0) -> 0 | I15: =ROUND(IFERROR(VLOOKUP(_xlfn.CONCAT($B15,$C15,$D15),$A$53:$C$9993,2,FALSE),0),0) -> 0 | K15: 0 | M15: ='[1]Payroll Summary by Department'!N62 -> 0 | O15: =M15 -> 0 | Q15: =O15 -> 0
A16: Retirement Contributions | B16: 00109130 | C16: 502200 | E16: =_xlfn.CONCAT(B16,C16,D16) -> 00109130502200 | G16: =ROUND(IFERROR(VLOOKUP(_xlfn.CONCAT($B16,$C16,$D16),$A$53:$C$9993,3,FALSE),0),0) -> 0 | I16: =ROUND(IFERROR(VLOOKUP(_xlfn.CONCAT($B16,$C16,$D16),$A$53:$C$9993,2,FALSE),0),0) -> 0 | K16: 0 | M16: ='[1]Payroll Summary by Department'!O62+'[1]Payroll Summary by Department'!P62 -> 0 | O16: =M16 -> 0 | Q16: =O16 -> 0
A17: Health Insurance | B17: 00109130 | C17: 502300 | E17: =_xlfn.CONCAT(B17,C17,D17) -> 00109130502300 | G17: =ROUND(IFERROR(VLOOKUP(_xlfn.CONCAT($B17,$C17,$D17),$A$53:$C$9993,3,FALSE),0),0) -> 0 | I17: =ROUND(IFERROR(VLOOKUP(_xlfn.CONCAT($B17,$C17,$D17),$A$53:$C$9993,2,FALSE),0),0) -> 0 | K17: 0 | M17: ='[1]Payroll Summary by Department'!Q62 -> 0 | O17: =M17 -> 0 | Q17: =O17 -> 0
A18: Life Insurance | B18: 00109130 | C18: 502400 | E18: =_xlfn.CONCAT(B18,C18,D18) -> 00109130502400 | G18: =ROUND(IFERROR(VLOOKUP(_xlfn.CONCAT($B18,$C18,$D18),$A$53:$C$9993,3,FALSE),0),0) -> 0 | I18: =ROUND(IFERROR(VLOOKUP(_xlfn.CONCAT($B18,$C18,$D18),$A$53:$C$9993,2,FALSE),0),0) -> 0 | K18: 0 | M18: ='[1]Payroll Summary by Department'!R62 -> 0 | O18: =M18 -> 0 | Q18: =O18 -> 0
A19: Total Personal Services | E19: =_xlfn.CONCAT(B19,C19,D19) | F19: $ | G19: =SUM(G12:G18) -> 0 | H19: $ | I19: =SUM(I12:I18) -> 0 | J19: $ | K19: =SUM(K12:K18) -> 0 | L19: $ | M19: =SUM(M12:M18) -> 0 | N19: $ | O19: =SUM(O12:O18) -> 0 | P19: $ | Q19: =SUM(Q12:Q18) -> 0
A20: POSITION ROSTER | E20: =_xlfn.CONCAT(B20,C20,D20)
A21: Full Time Employees | E21: =_xlfn.CONCAT(B21,C21,D21) | G21: 0 | I21: 0 | K21: 0 | M21: 0 | O21: =M21 -> 0
A22: Total Positions | E22: =_xlfn.CONCAT(B22,C22,D22) | G22: =SUM(G21:G21) -> 0 | I22: =SUM(I21:I21) -> 0 | K22: =SUM(K21:K21) -> 0 | M22: =SUM(M21:M21) -> 0 | O22: =SUM(O21:O21) -> 0
A23: OPERATING EXPENDITURES | E23: =_xlfn.CONCAT(B23,C23,D23)
A24: Professional Services-Architectural | B24: 00109130 | C24: 503140 | E24: =_xlfn.CONCAT(B24,C24,D24) -> 00109130503140 | F24: $ | G24: =ROUND(IFERROR(VLOOKUP(_xlfn.CONCAT($B24,$C24,$D24),$A$53:$C$9993,3,FALSE),0),0) -> 0 | H24: $ | I24: =ROUND(IFERROR(VLOOKUP(_xlfn.CONCAT($B24,$C24,$D24),$A$53:$C$9993,2,FALSE),0),0) -> 0 | J24: $ | K24: 0 | L24: $ | M24: 0 | N24: $ | O24: =M24 -> 0 | P24: $ | Q24: =O24 -> 0
A25: Other Contractual Services | B25: 00109130 | C25: 503499 | E25: =_xlfn.CONCAT(B25,C25,D25) -> 00109130503499 | F25: $ | G25: =ROUND(IFERROR(VLOOKUP(_xlfn.CONCAT($B25,$C25,$D25),$A$53:$C$9993,3,FALSE),0),0) -> 0 | H25: $ | I25: =ROUND(IFERROR(VLOOKUP(_xlfn.CONCAT($B25,$C25,$D25),$A$53:$C$9993,2,FALSE),0),0) -> 0 | J25: $ | K25: 1400 | L25: $ | M25: 1400 | N25: $ | O25: =M25 -> 1400 | P25: $ | Q25: =O25 -> 1400
A26: Repair/Maint-Bldgs/ Facilities | B26: 00109130 | C26: 504601 | E26: =_xlfn.CONCAT(B26,C26,D26) -> 00109130504601 | G26: =ROUND(IFERROR(VLOOKUP(_xlfn.CONCAT($B26,$C26,$D26),$A$53:$C$9993,3,FALSE),0),0) -> 0 | I26: =ROUND(IFERROR(VLOOKUP(_xlfn.CONCAT($B26,$C26,$D26),$A$53:$C$9993,2,FALSE),0),0) -> 2293 | K26: 2000 | M26: 2000 | O26: =M26 -> 2000 | Q26: =O26 -> 2000
A27: Repair/Maint-Fencing/Security | B27: 00109130 | C27: 504602 | E27: =_xlfn.CONCAT(B27,C27,D27) -> 00109130504602 | G27: =ROUND(IFERROR(VLOOKUP(_xlfn.CONCAT($B27,$C27,$D27),$A$53:$C$9993,3,FALSE),0),0) -> 2745 | I27: =ROUND(IFERROR(VLOOKUP(_xlfn.CONCAT($B27,$C27,$D27),$A$53:$C$9993,2,FALSE),0),0) -> 2574 | K27: 3000 | M27: 3000 | O27: =M27 -> 3000 | Q27: =O27 -> 3000
A28: Repair/Maint-Equipment | B28: 00109130 | C28: 504620 | E28: =_xlfn.CONCAT(B28,C28,D28) -> 00109130504620 | G28: =ROUND(IFERROR(VLOOKUP(_xlfn.CONCAT($B28,$C28,$D28),$A$53:$C$9993,3,FALSE),0),0) -> 2390 | I28: =ROUND(IFERROR(VLOOKUP(_xlfn.CONCAT($B28,$C28,$D28),$A$53:$C$9993,2,FALSE),0),0) -> 7851 | K28: 0 | M28: 0 | O28: =M28 -> 0 | Q28: =O28 -> 0
A29: Playground | B29: 00109130 | E29: =_xlfn.CONCAT(B29,C29,D29) -> 00109130 | G29: =ROUND(IFERROR(VLOOKUP(_xlfn.CONCAT($B29,$C29,$D29),$A$53:$C$9993,3,FALSE),0),0) -> 0 | I29: =ROUND(IFERROR(VLOOKUP(_xlfn.CONCAT($B29,$C29,$D29),$A$53:$C$9993,2,FALSE),0),0) -> 0 | K29: 5000 | M29: 5000 | O29: =M29 -> 5000 | Q29: =O29 -> 5000
A30: Groundcover | B30: 00109130 | E30: =_xlfn.CONCAT(B30,C30,D30) -> 00109130 | G30: =ROUND(IFERROR(VLOOKUP(_xlfn.CONCAT($B30,$C30,$D30),$A$53:$C$9993,3,FALSE),0),0) -> 0 | I30: =ROUND(IFERROR(VLOOKUP(_xlfn.CONCAT($B30,$C30,$D30),$A$53:$C$9993,2,FALSE),0),0) -> 0 | K30: 5000 | M30: 5000 | O30: =M30 -> 5000 | Q30: =O30 -> 5000
A31: Repair/Maint-Hardscape | B31: 00109130 | C31: 504675 | E31: =_xlfn.CONCAT(B31,C31,D31) -> 00109130504675 | G31: =ROUND(IFERROR(VLOOKUP(_xlfn.CONCAT($B31,$C31,$D31),$A$53:$C$9993,3,FALSE),0),0) -> 5622 | I31: =ROUND(IFERROR(VLOOKUP(_xlfn.CONCAT($B31,$C31,$D31),$A$53:$C$9993,2,FALSE),0),0) -> 2993 | K31: 6000 | M31: 6000 | O31: =M31 -> 6000 | Q31: =O31 -> 6000
A32: Repair/Maint-Technology | B32: 00109130 | C32: 504683 | E32: =_xlfn.CONCAT(B32,C32,D32) -> 00109130504683 | G32: =ROUND(IFERROR(VLOOKUP(_xlfn.CONCAT($B32,$C32,$D32),$A$53:$C$9993,3,FALSE),0),0) -> 0 | I32: =ROUND(IFERROR(VLOOKUP(_xlfn.CONCAT($B32,$C32,$D32),$A$53:$C$9993,2,FALSE),0),0) -> 2946
A33: Audio/Visual | B33: 00109130 | E33: =_xlfn.CONCAT(B33,C33,D33) -> 00109130 | G33: =ROUND(IFERROR(VLOOKUP(_xlfn.CONCAT($B33,$C33,$D33),$A$53:$C$9993,3,FALSE),0),0) -> 0 | I33: =ROUND(IFERROR(VLOOKUP(_xlfn.CONCAT($B33,$C33,$D33),$A$53:$C$9993,2,FALSE),0),0) -> 0 | K33: 2000 | M33: 2000 | O33: =M33 -> 2000 | Q33: =O33 -> 2000
A34: Repair/Maint-Other | B34: 00109130 | C34: 504699 | E34: =_xlfn.CONCAT(B34,C34,D34) -> 00109130504699 | G34: =ROUND(IFERROR(VLOOKUP(_xlfn.CONCAT($B34,$C34,$D34),$A$53:$C$9993,3,FALSE),0),0) -> 148 | I34: =ROUND(IFERROR(VLOOKUP(_xlfn.CONCAT($B34,$C34,$D34),$A$53:$C$9993,2,FALSE),0),0) -> 385 | K34: 4000 | M34: 4000 | O34: =M34 -> 4000 | Q34: =O34 -> 4000
A35: Printing and Binding | B35: 00109130 | C35: 504710 | E35: =_xlfn.CONCAT(B35,C35,D35) -> 00109130504710 | G35: =ROUND(IFERROR(VLOOKUP(_xlfn.CONCAT($B35,$C35,$D35),$A$53:$C$9993,3,FALSE),0),0) -> 0 | I35: =ROUND(IFERROR(VLOOKUP(_xlfn.CONCAT($B35,$C35,$D35),$A$53:$C$9993,2,FALSE),0),0) -> 0 | K35: 0 | M35: 0 | O35: =M35 -> 0 | Q35: =O35 -> 0
A36: Operating Supplies | B36: 00109130 | C36: 505201 | E36: =_xlfn.CONCAT(B36,C36,D36) -> 00109130505201 | G36: =ROUND(IFERROR(VLOOKUP(_xlfn.CONCAT($B36,$C36,$D36),$A$53:$C$9993,3,FALSE),0),0) -> 0 | I36: =ROUND(IFERROR(VLOOKUP(_xlfn.CONCAT($B36,$C36,$D36),$A$53:$C$9993,2,FALSE),0),0) -> 0 | K36: 0 | M36: 0 | O36: =M36 -> 0 | Q36: =O36 -> 0
A37: Rental Uniforms | B37: 00109130 | C37: 505505 | E37: =_xlfn.CONCAT(B37,C37,D37) -> 00109130505505 | G37: =ROUND(IFERROR(VLOOKUP(_xlfn.CONCAT($B37,$C37,$D37),$A$53:$C$9993,3,FALSE),0),0) -> 0 | I37: =ROUND(IFERROR(VLOOKUP(_xlfn.CONCAT($B37,$C37,$D37),$A$53:$C$9993,2,FALSE),0),0) -> 0 | K37: 0 | M37: 0 | O37: =M37 -> 0 | Q37: =O37 -> 0
A38: Boots/Shoes | B38: 00109130 | C38: 505532 | E38: =_xlfn.CONCAT(B38,C38,D38) -> 00109130505532 | G38: =ROUND(IFERROR(VLOOKUP(_xlfn.CONCAT($B38,$C38,$D38),$A$53:$C$9993,3,FALSE),0),0) -> 0 | I38: =ROUND(IFERROR(VLOOKUP(_xlfn.CONCAT($B38,$C38,$D38),$A$53:$C$9993,2,FALSE),0),0) -> 0 | K38: 0 | M38: 0 | O38: =M38 -> 0 | Q38: =O38 -> 0
A39: Safety Uniforms | B39: 00109130 | C39: 505540 | E39: =_xlfn.CONCAT(B39,C39,D39) -> 00109130505540 | G39: =ROUND(IFERROR(VLOOKUP(_xlfn.CONCAT($B39,$C39,$D39),$A$53:$C$9993,3,FALSE),0),0) -> 0 | I39: =ROUND(IFERROR(VLOOKUP(_xlfn.CONCAT($B39,$C39,$D39),$A$53:$C$9993,2,FALSE),0),0) -> 0 | K39: 0 | M39: 0 | O39: =M39 -> 0 | Q39: =O39 -> 0
A40: Purchased Uniforms | B40: 00109130 | C40: 505550 | E40: =_xlfn.CONCAT(B40,C40,D40) -> 00109130505550 | G40: =ROUND(IFERROR(VLOOKUP(_xlfn.CONCAT($B40,$C40,$D40),$A$53:$C$9993,3,FALSE),0),0) -> 0 | I40: =ROUND(IFERROR(VLOOKUP(_xlfn.CONCAT($B40,$C40,$D40),$A$53:$C$9993,2,FALSE),0),0) -> 0 | K40: 0 | M40: 0 | O40: =M40 -> 0 | Q40: =O40 -> 0
A41: Park Equipment < $5,000 | B41: 00109130 | C41: 505750 | E41: =_xlfn.CONCAT(B41,C41,D41) -> 00109130505750 | G41: =ROUND(IFERROR(VLOOKUP(_xlfn.CONCAT($B41,$C41,$D41),$A$53:$C$9993,3,FALSE),0),0) -> 1100 | I41: =ROUND(IFERROR(VLOOKUP(_xlfn.CONCAT($B41,$C41,$D41),$A$53:$C$9993,2,FALSE),0),0) -> 0 | K41: 1300 | M41: 1300 | O41: =M41 -> 1300 | Q41: =O41 -> 1300
A42: Technology Items < $5,000 | B42: 00109130 | C42: 505801 | E42: =_xlfn.CONCAT(B42,C42,D42) -> 00109130505801 | G42: =ROUND(IFERROR(VLOOKUP(_xlfn.CONCAT($B42,$C42,$D42),$A$53:$C$9993,3,FALSE),0),0) -> 0 | I42: =ROUND(IFERROR(VLOOKUP(_xlfn.CONCAT($B42,$C42,$D42),$A$53:$C$9993,2,FALSE),0),0) -> 0 | K42: 0 | M42: 0 | O42: =M42 -> 0 | Q42: =O42 -> 0
...

Sheet  914 Westmonte
A1: City of Altamonte Springs, Florida
A2: ='[1]Admin Summary'!A2:K2 -> Fiscal Year 2026 / 2027 Annual Budget
A4: Leisure and Maintenance Services Department
A5: Westmonte Park
A6: General Fund (00109140)
M8: =' 911 Admin'!M8 -> 2027
G9: =' 911 Admin'!G9 -> 2024 | I9: =' 911 Admin'!I9 -> 2025 | K9: =' 911 Admin'!K9 -> 2026 | M9: Department | O9: Manager | Q9: Commission
B10: Org | C10: Obj | D10: Proj | G10: Actual | I10: Actual | K10: Budget | M10: Requested | O10: Recommended | Q10: Adopted | R10: Notes
A11: PERSONNEL SERVICES
A12: Regular Salaries & Wages | B12: 00109140 | C12: 501201 | E12: =_xlfn.CONCAT(B12,C12,D12) -> 00109140501201 | F12: $ | G12: =ROUND(IFERROR(VLOOKUP(_xlfn.CONCAT($B12,$C12,$D12),$A$71:$C$9993,3,FALSE),0),0) -> 0 | H12: $ | I12: =ROUND(IFERROR(VLOOKUP(_xlfn.CONCAT($B12,$C12,$D12),$A$71:$C$9993,2,FALSE),0),0) -> 0 | J12: $ | K12: 0 | L12: $ | M12: ='[1]Payroll Summary by Department'!C63 -> 0 | N12: $ | O12: =M12 -> 0 | P12: $ | Q12: =O12 -> 0
A13: Limited Term-Recreation | B13: 00109140 | C13: 501305 | E13: =_xlfn.CONCAT(B13,C13,D13) -> 00109140501305 | G13: =ROUND(IFERROR(VLOOKUP(_xlfn.CONCAT($B13,$C13,$D13),$A$71:$C$9993,3,FALSE),0),0) -> 0 | I13: =ROUND(IFERROR(VLOOKUP(_xlfn.CONCAT($B13,$C13,$D13),$A$71:$C$9993,2,FALSE),0),0) -> 0 | K13: 0 | M13: 0 | O13: =M13 -> 0 | Q13: =O13 -> 0
A14: Overtime | B14: 00109140 | C14: 201400 | E14: =_xlfn.CONCAT(B14,C14,D14) -> 00109140201400 | G14: =ROUND(IFERROR(VLOOKUP(_xlfn.CONCAT($B14,$C14,$D14),$A$71:$C$9993,3,FALSE),0),0) -> 0 | I14: =ROUND(IFERROR(VLOOKUP(_xlfn.CONCAT($B14,$C14,$D14),$A$71:$C$9993,2,FALSE),0),0) -> 0 | K14: 0 | M14: 0 | O14: =M14 -> 0 | Q14: =O14 -> 0
A15: Add Pays | B15: 00109140 | C15: 501600 | E15: =_xlfn.CONCAT(B15,C15,D15) -> 00109140501600 | G15: =ROUND(IFERROR(VLOOKUP(_xlfn.CONCAT($B15,$C15,$D15),$A$71:$C$9993,3,FALSE),0),0) -> 0 | I15: =ROUND(IFERROR(VLOOKUP(_xlfn.CONCAT($B15,$C15,$D15),$A$71:$C$9993,2,FALSE),0),0) -> 0 | K15: 0 | M15: ='[1]Payroll Summary by Department'!I63 -> 0 | O15: =M15 -> 0 | Q15: =O15 -> 0
A16: Uniform Allowance | B16: 00109140 | C16: 501800 | E16: =_xlfn.CONCAT(B16,C16,D16) -> 00109140501800 | G16: =ROUND(IFERROR(VLOOKUP(_xlfn.CONCAT($B16,$C16,$D16),$A$71:$C$9993,3,FALSE),0),0) -> 0 | I16: =ROUND(IFERROR(VLOOKUP(_xlfn.CONCAT($B16,$C16,$D16),$A$71:$C$9993,2,FALSE),0),0) -> 0 | K16: 0 | M16: 0 | O16: =M16 -> 0 | Q16: =O16 -> 0
A17: FICA Taxes | B17: 00109140 | C17: 502100 | E17: =_xlfn.CONCAT(B17,C17,D17) -> 00109140502100 | G17: =ROUND(IFERROR(VLOOKUP(_xlfn.CONCAT($B17,$C17,$D17),$A$71:$C$9993,3,FALSE),0),0) -> 0 | I17: =ROUND(IFERROR(VLOOKUP(_xlfn.CONCAT($B17,$C17,$D17),$A$71:$C$9993,2,FALSE),0),0) -> 0 | K17: 0 | M17: ='[1]Payroll Summary by Department'!N63 -> 0 | O17: =M17 -> 0 | Q17: =O17 -> 0
A18: Retirement Contributions | B18: 00109140 | C18: 502200 | E18: =_xlfn.CONCAT(B18,C18,D18) -> 00109140502200 | G18: =ROUND(IFERROR(VLOOKUP(_xlfn.CONCAT($B18,$C18,$D18),$A$71:$C$9993,3,FALSE),0),0) -> 0 | I18: =ROUND(IFERROR(VLOOKUP(_xlfn.CONCAT($B18,$C18,$D18),$A$71:$C$9993,2,FALSE),0),0) -> 0 | K18: 0 | M18: ='[1]Payroll Summary by Department'!O63+'[1]Payroll Summary by Department'!P63 -> 0 | O18: =M18 -> 0 | Q18: =O18 -> 0
A19: Health Insurance | B19: 00109140 | C19: 502300 | E19: =_xlfn.CONCAT(B19,C19,D19) -> 00109140502300 | G19: =ROUND(IFERROR(VLOOKUP(_xlfn.CONCAT($B19,$C19,$D19),$A$71:$C$9993,3,FALSE),0),0) -> 0 | I19: =ROUND(IFERROR(VLOOKUP(_xlfn.CONCAT($B19,$C19,$D19),$A$71:$C$9993,2,FALSE),0),0) -> 0 | K19: 0 | M19: ='[1]Payroll Summary by Department'!Q63 -> 0 | O19: =M19 -> 0 | Q19: =O19 -> 0
A20: Life Insurance | B20: 00109140 | C20: 502400 | E20: =_xlfn.CONCAT(B20,C20,D20) -> 00109140502400 | G20: =ROUND(IFERROR(VLOOKUP(_xlfn.CONCAT($B20,$C20,$D20),$A$71:$C$9993,3,FALSE),0),0) -> 0 | I20: =ROUND(IFERROR(VLOOKUP(_xlfn.CONCAT($B20,$C20,$D20),$A$71:$C$9993,2,FALSE),0),0) -> 0 | K20: 0 | M20: ='[1]Payroll Summary by Department'!R63 -> 0 | O20: =M20 -> 0 | Q20: =O20 -> 0
A21: Total Personnel Services | E21: =_xlfn.CONCAT(B21,C21,D21) | F21: $ | G21: =SUM(G12:G20) -> 0 | H21: $ | I21: =SUM(I12:I20) -> 0 | J21: $ | K21: =SUM(K12:K20) -> 0 | L21: $ | M21: =SUM(M12:M20) -> 0 | N21: $ | O21: =SUM(O12:O20) -> 0 | P21: $ | Q21: =SUM(Q12:Q20) -> 0
A22: POSITION ROSTER | E22: =_xlfn.CONCAT(B22,C22,D22)
A23: Full-Time Employees | E23: =_xlfn.CONCAT(B23,C23,D23)
A24: Staff Assistant | C24: 4C | E24: =_xlfn.CONCAT(B24,C24,D24) -> 4C | G24: 0 | I24: 0 | K24: 0 | M24: 0 | O24: =M24 -> 0 | Q24: =O24 -> 0
A25: Total Positions | E25: =_xlfn.CONCAT(B25,C25,D25) | G25: =SUM(G24:G24) -> 0 | I25: =SUM(I24:I24) -> 0 | K25: =SUM(K24:K24) -> 0 | M25: =SUM(M24:M24) -> 0 | O25: =SUM(O24:O24) -> 0 | Q25: =SUM(Q24:Q24) -> 0
A26: OPERATING EXPENDITURES | E26: =_xlfn.CONCAT(B26,C26,D26)
A27: Other Services-Temporary Labor | B27: 00109140 | C27: 503450 | E27: =_xlfn.CONCAT(B27,C27,D27) -> 00109140503450 | F27: $ | G27: =ROUND(IFERROR(VLOOKUP(_xlfn.CONCAT($B27,$C27,$D27),$A$71:$C$9993,3,FALSE),0),0) -> 0 | H27: $ | I27: =ROUND(IFERROR(VLOOKUP(_xlfn.CONCAT($B27,$C27,$D27),$A$71:$C$9993,2,FALSE),0),0) -> 0 | J27: $ | K27: 0 | L27: $ | M27: 0 | N27: $ | O27: =M27 -> 0 | P27: $ | Q27: =O27 -> 0
A28: Other Services-Trash Disposal | B28: 00109140 | C28: 503460 | E28: =_xlfn.CONCAT(B28,C28,D28) -> 00109140503460 | F28: $ | G28: =ROUND(IFERROR(VLOOKUP(_xlfn.CONCAT($B28,$C28,$D28),$A$71:$C$9993,3,FALSE),0),0) -> 210 | H28: $ | I28: =ROUND(IFERROR(VLOOKUP(_xlfn.CONCAT($B28,$C28,$D28),$A$71:$C$9993,2,FALSE),0),0) -> 221 | J28: $ | K28: 300 | L28: $ | M28: 300 | N28: $ | O28: =M28 -> 300 | P28: $ | Q28: =O28 -> 300
A29: Rental/Lease-Equipment | B29: 00109140 | C29: 504430 | E29: =_xlfn.CONCAT(B29,C29,D29) -> 00109140504430 | G29: =ROUND(IFERROR(VLOOKUP(_xlfn.CONCAT($B29,$C29,$D29),$A$71:$C$9993,3,FALSE),0),0) -> 0 | I29: =ROUND(IFERROR(VLOOKUP(_xlfn.CONCAT($B29,$C29,$D29),$A$71:$C$9993,2,FALSE),0),0) -> 0 | K29: 0 | M29: 0 | O29: =M29 -> 0 | Q29: =O29 -> 0
A30: Rental/Lease-Network Connect | B30: 00109140 | C30: 504440 | E30: =_xlfn.CONCAT(B30,C30,D30) -> 00109140504440 | G30: =ROUND(IFERROR(VLOOKUP(_xlfn.CONCAT($B30,$C30,$D30),$A$71:$C$9993,3,FALSE),0),0) -> 2408 | I30: =ROUND(IFERROR(VLOOKUP(_xlfn.CONCAT($B30,$C30,$D30),$A$71:$C$9993,2,FALSE),0),0) -> 2707 | K30: 0 | M30: 0 | O30: =M30 -> 0 | Q30: =O30 -> 0
A31: Spectrum | B31: 00109140 | E31: =_xlfn.CONCAT(B31,C31,D31) -> 00109140 | G31: =ROUND(IFERROR(VLOOKUP(_xlfn.CONCAT($B31,$C31,$D31),$A$71:$C$9993,3,FALSE),0),0) -> 0 | I31: =ROUND(IFERROR(VLOOKUP(_xlfn.CONCAT($B31,$C31,$D31),$A$71:$C$9993,2,FALSE),0),0) -> 0 | K31: 3200 | M31: 3200 | O31: =M31 -> 3200 | Q31: =O31 -> 3200
A32: Repair/Maint-Bldgs/Facilities | B32: 00109140 | C32: 504601 | E32: =_xlfn.CONCAT(B32,C32,D32) -> 00109140504601 | G32: =ROUND(IFERROR(VLOOKUP(_xlfn.CONCAT($B32,$C32,$D32),$A$71:$C$9993,3,FALSE),0),0) -> 754 | I32: =ROUND(IFERROR(VLOOKUP(_xlfn.CONCAT($B32,$C32,$D32),$A$71:$C$9993,2,FALSE),0),0) -> 260 | K32: 1000 | M32: 1000 | O32: =M32 -> 1000 | Q32: =O32 -> 1000
A33: Repair/Maint-Fencing/Security | B33: 00109140 | C33: 504602 | E33: =_xlfn.CONCAT(B33,C33,D33) -> 00109140504602 | G33: =ROUND(IFERROR(VLOOKUP(_xlfn.CONCAT($B33,$C33,$D33),$A$71:$C$9993,3,FALSE),0),0) -> 6855 | I33: =ROUND(IFERROR(VLOOKUP(_xlfn.CONCAT($B33,$C33,$D33),$A$71:$C$9993,2,FALSE),0),0) -> 6073 | K33: 5000 | M33: 5000 | O33: =M33 -> 5000 | Q33: =O33 -> 5000
A34: Repair/Maint-Civic Center | B34: 00109140 | C34: 504605 | E34: =_xlfn.CONCAT(B34,C34,D34) -> 00109140504605 | G34: =ROUND(IFERROR(VLOOKUP(_xlfn.CONCAT($B34,$C34,$D34),$A$71:$C$9993,3,FALSE),0),0) -> 0 | I34: =ROUND(IFERROR(VLOOKUP(_xlfn.CONCAT($B34,$C34,$D34),$A$71:$C$9993,2,FALSE),0),0) -> 0 | K34: 0 | M34: 0 | O34: =M34 -> 0 | Q34: =O34 -> 0
A35: Repair/Maint-Ballfield | B35: 00109140 | C35: 504610 | E35: =_xlfn.CONCAT(B35,C35,D35) -> 00109140504610 | G35: =ROUND(IFERROR(VLOOKUP(_xlfn.CONCAT($B35,$C35,$D35),$A$71:$C$9993,3,FALSE),0),0) -> 0 | I35: =ROUND(IFERROR(VLOOKUP(_xlfn.CONCAT($B35,$C35,$D35),$A$71:$C$9993,2,FALSE),0),0) -> 0 | K35: 0 | M35: 0 | O35: =M35 -> 0 | Q35: =O35 -> 0
A36: Repair/Maint-Equipment | B36: 00109140 | C36: 504620 | E36: =_xlfn.CONCAT(B36,C36,D36) -> 00109140504620 | G36: =ROUND(IFERROR(VLOOKUP(_xlfn.CONCAT($B36,$C36,$D36),$A$71:$C$9993,3,FALSE),0),0) -> 82 | I36: =ROUND(IFERROR(VLOOKUP(_xlfn.CONCAT($B36,$C36,$D36),$A$71:$C$9993,2,FALSE),0),0) -> 0 | K36: 0 | M36: 0 | O36: =M36 -> 0 | Q36: =O36 -> 0
A37: Playground | B37: 00109140 | E37: =_xlfn.CONCAT(B37,C37,D37) -> 00109140 | G37: =ROUND(IFERROR(VLOOKUP(_xlfn.CONCAT($B37,$C37,$D37),$A$71:$C$9993,3,FALSE),0),0) -> 0 | I37: =ROUND(IFERROR(VLOOKUP(_xlfn.CONCAT($B37,$C37,$D37),$A$71:$C$9993,2,FALSE),0),0) -> 0 | K37: 2000 | M37: 2000 | O37: =M37 -> 2000 | Q37: =O37 -> 2000
A38: Thorguard | B38: 00109140 | E38: =_xlfn.CONCAT(B38,C38,D38) -> 00109140 | G38: =ROUND(IFERROR(VLOOKUP(_xlfn.CONCAT($B38,$C38,$D38),$A$71:$C$9993,3,FALSE),0),0) -> 0 | I38: =ROUND(IFERROR(VLOOKUP(_xlfn.CONCAT($B38,$C38,$D38),$A$71:$C$9993,2,FALSE),0),0) -> 0 | K38: 2500 | M38: 2500 | O38: =M38 -> 2500 | Q38: =O38 -> 2500
A39: Repair/Maint-Hardscape | B39: 00109140 | C39: 504675 | E39: =_xlfn.CONCAT(B39,C39,D39) -> 00109140504675 | G39: =ROUND(IFERROR(VLOOKUP(_xlfn.CONCAT($B39,$C39,$D39),$A$71:$C$9993,3,FALSE),0),0) -> 0 | I39: =ROUND(IFERROR(VLOOKUP(_xlfn.CONCAT($B39,$C39,$D39),$A$71:$C$9993,2,FALSE),0),0) -> 0 | K39: 3500 | M39: 3500 | O39: =M39 -> 3500 | Q39: =O39 -> 3500
A40: Repair/Maint-Service Contracts | B40: 00109140 | C40: 504680 | E40: =_xlfn.CONCAT(B40,C40,D40) -> 00109140504680 | G40: =ROUND(IFERROR(VLOOKUP(_xlfn.CONCAT($B40,$C40,$D40),$A$71:$C$9993,3,FALSE),0),0) -> 27713 | I40: =ROUND(IFERROR(VLOOKUP(_xlfn.CONCAT($B40,$C40,$D40),$A$71:$C$9993,2,FALSE),0),0) -> 17516 | K40: 0 | M40: 0 | O40: =M40 -> 0 | Q40: =O40 -> 0
A41: Pool Maintenance Services | B41: 00109140 | E41: =_xlfn.CONCAT(B41,C41,D41) -> 00109140 | G41: =ROUND(IFERROR(VLOOKUP(_xlfn.CONCAT($B41,$C41,$D41),$A$71:$C$9993,3,FALSE),0),0) -> 0 | I41: =ROUND(IFERROR(VLOOKUP(_xlfn.CONCAT($B41,$C41,$D41),$A$71:$C$9993,2,FALSE),0),0) -> 0 | K41: 40000 | M41: 40000 | O41: =M41 -> 40000 | Q41: =O41 -> 40000
A42: Repair/Maint-Technology | B42: 00109140 | C42: 504683 | E42: =_xlfn.CONCAT(B42,C42,D42) -> 00109140504683 | G42: =ROUND(IFERROR(VLOOKUP(_xlfn.CONCAT($B42,$C42,$D42),$A$71:$C$9993,3,FALSE),0),0) -> 3623 | I42: =ROUND(IFERROR(VLOOKUP(_xlfn.CONCAT($B42,$C42,$D42),$A$71:$C$9993,2,FALSE),0),0) -> 1050 | K42: 2000 | M42: 2000 | O42: =M42 -> 2000 | Q42: =O42 -> 2000
...

Sheet 916 Alta Rec
A1: City of Altamonte Springs, Florida
A2: ='[1]Admin Summary'!A2:K2 -> Fiscal Year 2026 / 2027 Annual Budget
A4: Leisure and Maintenance Services Department
A5: Altamonte Recreation
A6: General Fund (00109160)
M8: =' 911 Admin'!M8 -> 2027
G9: =' 911 Admin'!G9 -> 2024 | I9: =' 911 Admin'!I9 -> 2025 | K9: =' 911 Admin'!K9 -> 2026 | M9: Department | O9: Manager | Q9: Commission
B10: Org | C10: Obj | D10: Proj | G10: Actual | I10: Actual | K10: Budget | M10: Requested | O10: Recommended | Q10: Adopted | R10: Notes
A11: PERSONNEL SERVICES
A12: Regular Salaries & Wages Base: 16 Positions | B12: 00109160 | C12: 501201 | E12: =_xlfn.CONCAT(B12,C12,D12) -> 00109160501201 | F12: $ | G12: =ROUND(IFERROR(VLOOKUP(_xlfn.CONCAT($B12,$C12,$D12),$A$134:$C$9994,3,FALSE),0),0) -> 726081 | H12: $ | I12: =ROUND(IFERROR(VLOOKUP(_xlfn.CONCAT($B12,$C12,$D12),$A$134:$C$9994,2,FALSE),0),0) -> 777930 | J12: $ | K12: 790775 | L12: $ | M12: ='[1]Payroll Summary by Department'!C64 -> 790775 | N12: $ | O12: =M12 -> 790775 | P12: $ | Q12: =O12 -> 790775
A13: Sign Incentive Award | B13: 00109160 | C13: 501290 | E13: =_xlfn.CONCAT(B13,C13,D13) -> 00109160501290 | G13: =ROUND(IFERROR(VLOOKUP(_xlfn.CONCAT($B13,$C13,$D13),$A$134:$C$9994,3,FALSE),0),0) -> 0 | I13: =ROUND(IFERROR(VLOOKUP(_xlfn.CONCAT($B13,$C13,$D13),$A$134:$C$9994,2,FALSE),0),0) -> 0 | K13: 0 | M13: 0 | O13: =M13 -> 0 | Q13: =O13 -> 0
A14: Limited Term - Recreation | B14: 00109160 | C14: 501305 | E14: =_xlfn.CONCAT(B14,C14,D14) -> 00109160501305 | G14: =ROUND(IFERROR(VLOOKUP(_xlfn.CONCAT($B14,$C14,$D14),$A$134:$C$9994,3,FALSE),0),0) -> 871410 | I14: =ROUND(IFERROR(VLOOKUP(_xlfn.CONCAT($B14,$C14,$D14),$A$134:$C$9994,2,FALSE),0),0) -> 149587 | K14: 0 | M14: 0 | O14: =M14 -> 0 | Q14: =O14 -> 0
A15: Baseball Instructors | B15: 00109160 | C15: 501305 | D15: ABAIN | E15: =_xlfn.CONCAT(B15,C15,D15) -> 00109160501305ABAIN | G15: =ROUND(IFERROR(VLOOKUP(_xlfn.CONCAT($B15,$C15,$D15),$A$134:$C$9994,3,FALSE),0),0) -> 0 | I15: =ROUND(IFERROR(VLOOKUP(_xlfn.CONCAT($B15,$C15,$D15),$A$134:$C$9994,2,FALSE),0),0) -> 213636 | K15: 225000 | M15: 225000 | O15: =M15 -> 225000 | Q15: =O15 -> 225000
A16: Softball Instructors | B16: 00109160 | C16: 501305 | D16: AFAIN | E16: =_xlfn.CONCAT(B16,C16,D16) -> 00109160501305AFAIN | G16: =ROUND(IFERROR(VLOOKUP(_xlfn.CONCAT($B16,$C16,$D16),$A$134:$C$9994,3,FALSE),0),0) -> 0 | I16: =ROUND(IFERROR(VLOOKUP(_xlfn.CONCAT($B16,$C16,$D16),$A$134:$C$9994,2,FALSE),0),0) -> 53685 | K16: 75000 | M16: 75000 | O16: =M16 -> 75000 | Q16: =O16 -> 75000
A17: Teen Leaders | B17: 00109160 | C17: 501305 | D17: TEENL | E17: =_xlfn.CONCAT(B17,C17,D17) -> 00109160501305TEENL | G17: =ROUND(IFERROR(VLOOKUP(_xlfn.CONCAT($B17,$C17,$D17),$A$134:$C$9994,3,FALSE),0),0) -> 0 | I17: =ROUND(IFERROR(VLOOKUP(_xlfn.CONCAT($B17,$C17,$D17),$A$134:$C$9994,2,FALSE),0),0) -> 13306 | K17: 12600 | M17: 12600 | O17: =M17 -> 12600 | Q17: =O17 -> 12600
A18: Teen Aides | B18: 00109160 | C18: 501305 | D18: TEENA | E18: =_xlfn.CONCAT(B18,C18,D18) -> 00109160501305TEENA | G18: =ROUND(IFERROR(VLOOKUP(_xlfn.CONCAT($B18,$C18,$D18),$A$134:$C$9994,3,FALSE),0),0) -> 0 | I18: =ROUND(IFERROR(VLOOKUP(_xlfn.CONCAT($B18,$C18,$D18),$A$134:$C$9994,2,FALSE),0),0) -> 10350 | K18: 11500 | M18: 11500 | O18: =M18 -> 11500 | Q18: =O18 -> 11500
A19: Bus Driver | B19: 00109160 | C19: 501305 | D19: BUSDR | E19: =_xlfn.CONCAT(B19,C19,D19) -> 00109160501305BUSDR | G19: =ROUND(IFERROR(VLOOKUP(_xlfn.CONCAT($B19,$C19,$D19),$A$134:$C$9994,3,FALSE),0),0) -> 0 | I19: =ROUND(IFERROR(VLOOKUP(_xlfn.CONCAT($B19,$C19,$D19),$A$134:$C$9994,2,FALSE),0),0) -> 8134 | K19: 10000 | M19: 10000 | O19: =M19 -> 10000 | Q19: =O19 -> 10000
A20: Playground Leaders | B20: 00109160 | C20: 501305 | D20: PLAYL | E20: =_xlfn.CONCAT(B20,C20,D20) -> 00109160501305PLAYL | G20: =ROUND(IFERROR(VLOOKUP(_xlfn.CONCAT($B20,$C20,$D20),$A$134:$C$9994,3,FALSE),0),0) -> 0 | I20: =ROUND(IFERROR(VLOOKUP(_xlfn.CONCAT($B20,$C20,$D20),$A$134:$C$9994,2,FALSE),0),0) -> 29850 | K20: 28000 | M20: 28000 | O20: =M20 -> 28000 | Q20: =O20 -> 28000
A21: Playground Aides | B21: 00109160 | C21: 501305 | D21: PLAYA | E21: =_xlfn.CONCAT(B21,C21,D21) -> 00109160501305PLAYA | G21: =ROUND(IFERROR(VLOOKUP(_xlfn.CONCAT($B21,$C21,$D21),$A$134:$C$9994,3,FALSE),0),0) -> 0 | I21: =ROUND(IFERROR(VLOOKUP(_xlfn.CONCAT($B21,$C21,$D21),$A$134:$C$9994,2,FALSE),0),0) -> 111330 | K21: 124000 | M21: 124000 | O21: =M21 -> 124000 | Q21: =O21 -> 124000
A22: Exercise Instructors | B22: 00109160 | C22: 501305 | D22: EXERC | E22: =_xlfn.CONCAT(B22,C22,D22) -> 00109160501305EXERC | G22: =ROUND(IFERROR(VLOOKUP(_xlfn.CONCAT($B22,$C22,$D22),$A$134:$C$9994,3,FALSE),0),0) -> 0 | I22: =ROUND(IFERROR(VLOOKUP(_xlfn.CONCAT($B22,$C22,$D22),$A$134:$C$9994,2,FALSE),0),0) -> 76190 | K22: 81000 | M22: 81000 | O22: =M22 -> 81000 | Q22: =O22 -> 81000
A23: Recreation Workers | B23: 00109160 | C23: 501305 | D23: RECW | E23: =_xlfn.CONCAT(B23,C23,D23) -> 00109160501305RECW | G23: =ROUND(IFERROR(VLOOKUP(_xlfn.CONCAT($B23,$C23,$D23),$A$134:$C$9994,3,FALSE),0),0) -> 0 | I23: =ROUND(IFERROR(VLOOKUP(_xlfn.CONCAT($B23,$C23,$D23),$A$134:$C$9994,2,FALSE),0),0) -> 35398 | K23: 58500 | M23: 58500 | O23: =M23 -> 58500 | Q23: =O23 -> 58500
A24: Basketball Instructor | B24: 00109160 | C24: 501305 | D24: ABLIN | E24: =_xlfn.CONCAT(B24,C24,D24) -> 00109160501305ABLIN | G24: =ROUND(IFERROR(VLOOKUP(_xlfn.CONCAT($B24,$C24,$D24),$A$134:$C$9994,3,FALSE),0),0) -> 0 | I24: =ROUND(IFERROR(VLOOKUP(_xlfn.CONCAT($B24,$C24,$D24),$A$134:$C$9994,2,FALSE),0),0) -> 14610 | K24: 30000 | M24: 30000 | O24: =M24 -> 30000 | Q24: =O24 -> 30000
A25: Park Rangers | B25: 00109160 | E25: =_xlfn.CONCAT(B25,C25,D25) -> 00109160 | G25: =ROUND(IFERROR(VLOOKUP(_xlfn.CONCAT($B25,$C25,$D25),$A$134:$C$9994,3,FALSE),0),0) -> 0 | I25: =ROUND(IFERROR(VLOOKUP(_xlfn.CONCAT($B25,$C25,$D25),$A$134:$C$9994,2,FALSE),0),0) -> 0 | K25: 0 | M25: 0 | O25: =M25 -> 0 | Q25: =O25 -> 0
A26: Limited Term-Lifeguards | B26: 00109160 | C26: 501312 | D26: LIFEG | E26: =_xlfn.CONCAT(B26,C26,D26) -> 00109160501312LIFEG | G26: =ROUND(IFERROR(VLOOKUP(_xlfn.CONCAT($B26,$C26,$D26),$A$134:$C$9994,3,FALSE),0),0)+ROUND(IFERROR(VLOOKUP("00109160501312",$A$134:$C$9994,3,FALSE),0),0) -> 244063 | I26: =ROUND(IFERROR(VLOOKUP(_xlfn.CONCAT($B26,$C26,$D26),$A$134:$C$9994,2,FALSE),0),0)+ROUND(IFERROR(VLOOKUP("00109160501312",$A$134:$C$9994,2,FALSE),0),0) -> 221714 | K26: 218000 | M26: 218000 | O26: =M26 -> 218000 | Q26: =O26 -> 218000
A27: Limited Term-Adapted Aquatics | B27: 00109160 | C27: 501313 | E27: =_xlfn.CONCAT(B27,C27,D27) -> 00109160501313 | G27: =ROUND(IFERROR(VLOOKUP(_xlfn.CONCAT($B27,$C27,$D27),$A$134:$C$9994,3,FALSE),0),0) -> 0 | I27: =ROUND(IFERROR(VLOOKUP(_xlfn.CONCAT($B27,$C27,$D27),$A$134:$C$9994,2,FALSE),0),0) -> 0 | K27: 0 | M27: 0 | O27: =M27 -> 0 | Q27: =O27 -> 0
A28: Limited Term-ABA/AFA Coach | B28: 00109160 | C28: 501314 | D28: TRVLB | E28: =_xlfn.CONCAT(B28,C28,D28) -> 00109160501314TRVLB | G28: =ROUND(IFERROR(VLOOKUP(_xlfn.CONCAT($B28,$C28,$D28),$A$134:$C$9994,3,FALSE),0),0) -> 0 | I28: =ROUND(IFERROR(VLOOKUP(_xlfn.CONCAT($B28,$C28,$D28),$A$134:$C$9994,2,FALSE),0),0) -> 61979 | K28: 98250 | M28: 98250 | O28: =M28 -> 98250 | Q28: =O28 -> 98250
A29: Limited Term-Babe Ruth Coach | B29: 00109160 | C29: 501314 | D29: BRUTH | E29: =_xlfn.CONCAT(B29,C29,D29) -> 00109160501314BRUTH | G29: =ROUND(IFERROR(VLOOKUP(_xlfn.CONCAT($B29,$C29,$D29),$A$134:$C$9994,3,FALSE),0),0)+ROUND(IFERROR(VLOOKUP("00109160501314",$A$134:$C$9994,3,FALSE),0),0) -> 114216 | I29: =ROUND(IFERROR(VLOOKUP(_xlfn.CONCAT($B29,$C29,$D29),$A$134:$C$9994,2,FALSE),0),0)+ROUND(IFERROR(VLOOKUP("00109160501314",$A$134:$C$9994,2,FALSE),0),0) -> 47537 | K29: 20000 | M29: 20000 | O29: =M29 -> 20000 | Q29: =O29 -> 20000
A30: Overtime | B30: 00109160 | C30: 501400 | E30: =_xlfn.CONCAT(B30,C30,D30) -> 00109160501400 | G30: =ROUND(IFERROR(VLOOKUP(_xlfn.CONCAT($B30,$C30,$D30),$A$134:$C$9994,3,FALSE),0),0) -> 8148 | I30: =ROUND(IFERROR(VLOOKUP(_xlfn.CONCAT($B30,$C30,$D30),$A$134:$C$9994,2,FALSE),0),0) -> 12828 | K30: 8000 | M30: 8000 | O30: =M30 -> 8000 | Q30: =O30 -> 8000
A31: Overtime-Playground Aides | B31: 00109160 | C31: 501400 | D31: PLAYA | E31: =_xlfn.CONCAT(B31,C31,D31) -> 00109160501400PLAYA | G31: =ROUND(IFERROR(VLOOKUP(_xlfn.CONCAT($B31,$C31,$D31),$A$134:$C$9994,3,FALSE),0),0) -> 0 | I31: =ROUND(IFERROR(VLOOKUP(_xlfn.CONCAT($B31,$C31,$D31),$A$134:$C$9994,2,FALSE),0),0) -> 360 | K31: 0 | M31: 0 | O31: =M31 -> 0 | Q31: =O31 -> 0
A32: On-Call | B32: 00109160 | C32: 501401 | E32: =_xlfn.CONCAT(B32,C32,D32) -> 00109160501401 | G32: =ROUND(IFERROR(VLOOKUP(_xlfn.CONCAT($B32,$C32,$D32),$A$134:$C$9994,3,FALSE),0),0) -> 0 | I32: =ROUND(IFERROR(VLOOKUP(_xlfn.CONCAT($B32,$C32,$D32),$A$134:$C$9994,2,FALSE),0),0) -> 0 | K32: 100 | M32: 100 | O32: =M32 -> 100 | Q32: =O32 -> 100
A33: Add Pays | B33: 00109160 | C33: 501600 | E33: =_xlfn.CONCAT(B33,C33,D33) -> 00109160501600 | G33: =ROUND(IFERROR(VLOOKUP(_xlfn.CONCAT($B33,$C33,$D33),$A$134:$C$9994,3,FALSE),0),0) -> 5454 | I33: =ROUND(IFERROR(VLOOKUP(_xlfn.CONCAT($B33,$C33,$D33),$A$134:$C$9994,2,FALSE),0),0) -> 1755 | K33: 5200 | M33: 5200 | O33: =M33 -> 5200 | Q33: =O33 -> 5200
A34: Auto Allowance | B34: 00109160 | C34: 501701 | E34: =_xlfn.CONCAT(B34,C34,D34) -> 00109160501701 | G34: =ROUND(IFERROR(VLOOKUP(_xlfn.CONCAT($B34,$C34,$D34),$A$134:$C$9994,3,FALSE),0),0) -> 0 | I34: =ROUND(IFERROR(VLOOKUP(_xlfn.CONCAT($B34,$C34,$D34),$A$134:$C$9994,2,FALSE),0),0) -> 0 | K34: 0 | M34: ='[1]Payroll Summary by Department'!K64 -> 0 | O34: =M34 -> 0 | Q34: =O34 -> 0
A35: Cell Phone Allowance | B35: 00109160 | C35: 501702 | E35: =_xlfn.CONCAT(B35,C35,D35) -> 00109160501702 | G35: =ROUND(IFERROR(VLOOKUP(_xlfn.CONCAT($B35,$C35,$D35),$A$134:$C$9994,3,FALSE),0),0) -> 4400 | I35: =ROUND(IFERROR(VLOOKUP(_xlfn.CONCAT($B35,$C35,$D35),$A$134:$C$9994,2,FALSE),0),0) -> 4981 | K35: 4800 | M35: ='[1]Payroll Summary by Department'!L64 -> 4800 | O35: =M35 -> 4800 | Q35: =O35 -> 4800
A36: Uniform Allowance | B36: 00109160 | C36: 501800 | E36: =_xlfn.CONCAT(B36,C36,D36) -> 00109160501800 | G36: =ROUND(IFERROR(VLOOKUP(_xlfn.CONCAT($B36,$C36,$D36),$A$134:$C$9994,3,FALSE),0),0) -> 0 | I36: =ROUND(IFERROR(VLOOKUP(_xlfn.CONCAT($B36,$C36,$D36),$A$134:$C$9994,2,FALSE),0),0) -> 0 | K36: 0 | M36: 0 | O36: =M36 -> 0 | Q36: =O36 -> 0
A37: ARPA Reimbursement Quarantine | B37: 00109160 | C37: 501900 | D37: 6.01N | E37: =_xlfn.CONCAT(B37,C37,D37) -> 001091605019006.01N | G37: =ROUND(IFERROR(VLOOKUP(_xlfn.CONCAT($B37,$C37,$D37),$A$134:$C$9994,3,FALSE),0),0) -> 0 | I37: =ROUND(IFERROR(VLOOKUP(_xlfn.CONCAT($B37,$C37,$D37),$A$134:$C$9994,2,FALSE),0),0) -> 0 | K37: 0 | M37: 0 | O37: =M37 -> 0 | Q37: =O37 -> 0
A38: ARPA Reimbursement Vaccine | B38: 00109160 | C38: 501900 | D38: 6.01O | E38: =_xlfn.CONCAT(B38,C38,D38) -> 001091605019006.01O | G38: =ROUND(IFERROR(VLOOKUP(_xlfn.CONCAT($B38,$C38,$D38),$A$134:$C$9994,3,FALSE),0),0) -> 0 | I38: =ROUND(IFERROR(VLOOKUP(_xlfn.CONCAT($B38,$C38,$D38),$A$134:$C$9994,2,FALSE),0),0) -> 0 | K38: 0 | M38: 0 | O38: =M38 -> 0 | Q38: =O38 -> 0
A39: FICA Taxes | B39: 00109160 | C39: 502100 | E39: =_xlfn.CONCAT(B39,C39,D39) -> 00109160502100 | G39: =ROUND(IFERROR(VLOOKUP(_xlfn.CONCAT($B39,$C39,$D39),$A$134:$C$9994,3,FALSE),0),0)+ROUND(IFERROR(VLOOKUP("00109160502100ABAIN",$A$134:$C$9994,3,FALSE),0),0)+ROUND(IFERROR(VLOOKUP("00109160502100ABLIN",$A$134:$C$9994,3,FALSE),0),0)+ROUND(IFERROR(VLOOKUP("00109160502100AFAIN",$A$134:$C$9994,3,FALSE),0),0)+ROUND(IFERROR(VLOOKUP("00109160502100BRUTH",$A$134:$C$9994,3,FALSE),0),0)+ROUND(IFERROR(VLOOKUP("00109160502100BUSDR",$A$134:$C$9994,3,FALSE),0),0)+ROUND(IFERROR(VLOOKUP("00109160502100CIALS",$A$134:$C$9994,3,FALSE),0),0)+ROUND(IFERROR(VLOOKUP("00109160502100EXERC",$A$134:$C$9994,3,FALSE),0),0)+ROUND(IFERROR(VLOOKUP("00109160502100LIFEG",$A$134:$C$9994,3,FALSE),0),0)+ROUND(IFERROR(VLOOKUP("00109160502100PLAYA",$A$134:$C$9994,3,FALSE),0),0)+ROUND(IFERROR(VLOOKUP("00109160502100PLAYL",$A$134:$C$9994,3,FALSE),0),0)+ROUND(IFERROR(VLOOKUP("00109160502100RECW",$A$134:$C$9994,3,FALSE),0),0)+ROUND(IFERROR(VLOOKUP("00109160502100TEENA",$A$134:$C$9994,3,FALSE),0),0)+ROUND(IFERROR(VLOOKUP("00109160502100TEENL",$A$134:$C$9994,3,FALSE),0),0)+ROUND(IFERROR(VLOOKUP("00109160502100TRVLB",$A$134:$C$9994,3,FALSE),0),0) -> 150086 | I39: =ROUND(IFERROR(VLOOKUP(_xlfn.CONCAT($B39,$C39,$D39),$A$134:$C$9994,2,FALSE),0),0)+ROUND(IFERROR(VLOOKUP("00109160502100ABAIN",$A$134:$C$9994,2,FALSE),0),0)+ROUND(IFERROR(VLOOKUP("00109160502100ABLIN",$A$134:$C$9994,2,FALSE),0),0)+ROUND(IFERROR(VLOOKUP("00109160502100AFAIN",$A$134:$C$9994,2,FALSE),0),0)+ROUND(IFERROR(VLOOKUP("00109160502100BRUTH",$A$134:$C$9994,2,FALSE),0),0)+ROUND(IFERROR(VLOOKUP("00109160502100BUSDR",$A$134:$C$9994,2,FALSE),0),0)+ROUND(IFERROR(VLOOKUP("00109160502100CIALS",$A$134:$C$9994,2,FALSE),0),0)+ROUND(IFERROR(VLOOKUP("00109160502100EXERC",$A$134:$C$9994,2,FALSE),0),0)+ROUND(IFERROR(VLOOKUP("00109160502100LIFEG",$A$134:$C$9994,2,FALSE),0),0)+ROUND(IFERROR(VLOOKUP("00109160502100PLAYA",$A$134:$C$9994,2,FALSE),0),0)+ROUND(IFERROR(VLOOKUP("00109160502100PLAYL",$A$134:$C$9994,2,FALSE),0),0)+ROUND(IFERROR(VLOOKUP("00109160502100RECW",$A$134:$C$9994,2,FALSE),0),0)+ROUND(IFERROR(VLOOKUP("00109160502100TEENA",$A$134:$C$9994,2,FALSE),0),0)+ROUND(IFERROR(VLOOKUP("00109160502100TEENL",$A$134:$C$9994,2,FALSE),0),0)+ROUND(IFERROR(VLOOKUP("00109160502100TRVLB",$A$134:$C$9994,2,FALSE),0),0) -> 140141 | K39: 130145 | M39: ='[1]Payroll Summary by Department'!N64 -> 130145 | O39: =M39 -> 130145 | Q39: =O39 -> 130145
A40: Retirement Contributions | B40: 00109160 | C40: 502200 | E40: =_xlfn.CONCAT(B40,C40,D40) -> 00109160502200 | G40: =ROUND(IFERROR(VLOOKUP(_xlfn.CONCAT($B40,$C40,$D40),$A$134:$C$9994,3,FALSE),0),0) -> 79846 | I40: =ROUND(IFERROR(VLOOKUP(_xlfn.CONCAT($B40,$C40,$D40),$A$134:$C$9994,2,FALSE),0),0) -> 75814 | K40: 99019 | M40: ='[1]Payroll Summary by Department'!O64+'[1]Payroll Summary by Department'!P64 -> 99019 | O40: =M40 -> 99019 | Q40: =O40 -> 99019
A41: Health Insurance | B41: 00109160 | C41: 502300 | E41: =_xlfn.CONCAT(B41,C41,D41) -> 00109160502300 | G41: =ROUND(IFERROR(VLOOKUP(_xlfn.CONCAT($B41,$C41,$D41),$A$134:$C$9994,3,FALSE),0),0) -> 137339 | I41: =ROUND(IFERROR(VLOOKUP(_xlfn.CONCAT($B41,$C41,$D41),$A$134:$C$9994,2,FALSE),0),0) -> 144290 | K41: 184288 | M41: ='[1]Payroll Summary by Department'!Q64 -> 184288 | O41: =M41 -> 184288 | Q41: =O41 -> 184288
A42: Life Insurance | B42: 00109160 | C42: 502400 | E42: =_xlfn.CONCAT(B42,C42,D42) -> 00109160502400 | G42: =ROUND(IFERROR(VLOOKUP(_xlfn.CONCAT($B42,$C42,$D42),$A$134:$C$9994,3,FALSE),0),0) -> 1408 | I42: =ROUND(IFERROR(VLOOKUP(_xlfn.CONCAT($B42,$C42,$D42),$A$134:$C$9994,2,FALSE),0),0) -> 1568 | K42: 1494 | M42: ='[1]Payroll Summary by Department'!R64 -> 1494 | O42: =M42 -> 1494 | Q42: =O42 -> 1494
...

Sheet 908 Brantley
A1: City of Altamonte Springs, Florida
A2: ='[1]Admin Summary'!A2:K2 -> Fiscal Year 2026 / 2027 Annual Budget
A4: Leisure and Maintenance Services Department
A5: Lake Brantley Sports Complex
A6: General Fund (00109080)
M8: =' 911 Admin'!M8 -> 2027
G9: =' 911 Admin'!G9 -> 2024 | I9: =' 911 Admin'!I9 -> 2025 | K9: =' 911 Admin'!K9 -> 2026 | M9: Department | O9: Manager | Q9: Commission
B10: Org | C10: Obj | D10: Proj | G10: Actual | I10: Actual | K10: Budget | M10: Requested | O10: Recommended | Q10: Adopted | R10: Notes
A11: PERSONNEL SERVICES
A12: Limited Term Employee Wages | B12: 00109080 | C12: 501300 | E12: =_xlfn.CONCAT(B12,C12,D12) -> 00109080501300 | G12: =ROUND(IFERROR(VLOOKUP(_xlfn.CONCAT($B12,$C12,$D12),$A$45:$C$9994,3,FALSE),0),0) -> 0 | I12: =ROUND(IFERROR(VLOOKUP(_xlfn.CONCAT($B12,$C12,$D12),$A$45:$C$9994,2,FALSE),0),0) -> 0 | K12: 0 | M12: 0 | O12: =M12 -> 0 | Q12: =O12 -> 0
A13: Limited Term-Recreation | B13: 00109080 | C13: 501305 | E13: =_xlfn.CONCAT(B13,C13,D13) -> 00109080501305 | F13: $ | G13: =ROUND(IFERROR(VLOOKUP(_xlfn.CONCAT($B13,$C13,$D13),$A$45:$C$9994,3,FALSE),0),0) -> 53055 | H13: $ | I13: =ROUND(IFERROR(VLOOKUP(_xlfn.CONCAT($B13,$C13,$D13),$A$45:$C$9994,2,FALSE),0),0) -> 49606 | J13: $ | K13: 22500 | L13: $ | M13: 22500 | N13: $ | O13: =M13 -> 22500 | P13: $ | Q13: =O13 -> 22500
A14: FICA Taxes | B14: 00109080 | C14: 502100 | E14: =_xlfn.CONCAT(B14,C14,D14) -> 00109080502100 | G14: =ROUND(IFERROR(VLOOKUP(_xlfn.CONCAT($B14,$C14,$D14),$A$45:$C$9994,3,FALSE),0),0) -> 4059 | I14: =ROUND(IFERROR(VLOOKUP(_xlfn.CONCAT($B14,$C14,$D14),$A$45:$C$9994,2,FALSE),0),0) -> 3795 | K14: 1721 | M14: ='[1]Payroll Summary by Department'!N58 -> 1721 | O14: =M14 -> 1721 | Q14: =O14 -> 1721
A15: Total Personnel Services | E15: =_xlfn.CONCAT(B15,C15,D15) | F15: $ | G15: =SUM(G12:G14) -> 57114 | H15: $ | I15: =SUM(I12:I14) -> 53401 | J15: $ | K15: =SUM(K12:K14) -> 24221 | L15: $ | M15: =SUM(M12:M14) -> 24221 | N15: $ | O15: =SUM(O12:O14) -> 24221 | P15: $ | Q15: =SUM(Q12:Q14) -> 24221
A16: OPERATING EXPENDITURES | E16: =_xlfn.CONCAT(B16,C16,D16)
A17: Utilities-Energy/Power | B17: 00109080 | C17: 504310 | E17: =_xlfn.CONCAT(B17,C17,D17) -> 00109080504310 | F17: $ | G17: =ROUND(IFERROR(VLOOKUP(_xlfn.CONCAT($B17,$C17,$D17),$A$45:$C$9994,3,FALSE),0),0) -> 6800 | H17: $ | I17: =ROUND(IFERROR(VLOOKUP(_xlfn.CONCAT($B17,$C17,$D17),$A$45:$C$9994,2,FALSE),0),0) -> 6800 | J17: $ | K17: 6800 | L17: $ | M17: 6800 | N17: $ | O17: =M17 -> 6800 | P17: $ | Q17: =O17 -> 6800
A18: Rental/Lease-Facilities | B18: 00109080 | C18: 504450 | E18: =_xlfn.CONCAT(B18,C18,D18) -> 00109080504450 | G18: =ROUND(IFERROR(VLOOKUP(_xlfn.CONCAT($B18,$C18,$D18),$A$45:$C$9994,3,FALSE),0),0) -> 0 | I18: =ROUND(IFERROR(VLOOKUP(_xlfn.CONCAT($B18,$C18,$D18),$A$45:$C$9994,2,FALSE),0),0) -> 466
A19: Ballfield LBHS/Softball | B19: 00109080 | E19: =_xlfn.CONCAT(B19,C19,D19) -> 00109080 | G19: =ROUND(IFERROR(VLOOKUP(_xlfn.CONCAT($B19,$C19,$D19),$A$45:$C$9994,3,FALSE),0),0) -> 0 | I19: =ROUND(IFERROR(VLOOKUP(_xlfn.CONCAT($B19,$C19,$D19),$A$45:$C$9994,2,FALSE),0),0) -> 0 | K19: 5000 | M19: 5000 | O19: =M19 -> 5000 | Q19: =O19 -> 5000
A20: Repair/Maint-Bldgs/Facilities | B20: 00109080 | C20: 504601 | E20: =_xlfn.CONCAT(B20,C20,D20) -> 00109080504601 | G20: =ROUND(IFERROR(VLOOKUP(_xlfn.CONCAT($B20,$C20,$D20),$A$45:$C$9994,3,FALSE),0),0) -> 20206 | I20: =ROUND(IFERROR(VLOOKUP(_xlfn.CONCAT($B20,$C20,$D20),$A$45:$C$9994,2,FALSE),0),0) -> 19340 | K20: 0 | M20: 0 | O20: =M20 -> 0 | Q20: =O20 -> 0
A21: Field House Gym | B21: 00109080 | E21: =_xlfn.CONCAT(B21,C21,D21) -> 00109080 | G21: =ROUND(IFERROR(VLOOKUP(_xlfn.CONCAT($B21,$C21,$D21),$A$45:$C$9994,3,FALSE),0),0) -> 0 | I21: =ROUND(IFERROR(VLOOKUP(_xlfn.CONCAT($B21,$C21,$D21),$A$45:$C$9994,2,FALSE),0),0) -> 0 | K21: 0 | Q21: =O21 -> 0
A22: Resurface Gym Floors | B22: 00109080 | E22: =_xlfn.CONCAT(B22,C22,D22) -> 00109080 | G22: =ROUND(IFERROR(VLOOKUP(_xlfn.CONCAT($B22,$C22,$D22),$A$45:$C$9994,3,FALSE),0),0) -> 0 | I22: =ROUND(IFERROR(VLOOKUP(_xlfn.CONCAT($B22,$C22,$D22),$A$45:$C$9994,2,FALSE),0),0) -> 0 | K22: 15000 | M22: 15000 | O22: =M22 -> 15000 | Q22: =O22 -> 15000
A23: Gym Cleaning/Field House | B23: 00109080 | E23: =_xlfn.CONCAT(B23,C23,D23) -> 00109080 | G23: =ROUND(IFERROR(VLOOKUP(_xlfn.CONCAT($B23,$C23,$D23),$A$45:$C$9994,3,FALSE),0),0) -> 0 | I23: =ROUND(IFERROR(VLOOKUP(_xlfn.CONCAT($B23,$C23,$D23),$A$45:$C$9994,2,FALSE),0),0) -> 0 | K23: 5000 | M23: 5000 | O23: =M23 -> 5000 | Q23: =O23 -> 5000
